Workbook
Name Slicer_LoanProduct: #N/A
Name Slicer_Months__DisbursementDate: #N/A
Name Slicer_Region: #N/A

Sheet BusinessProblem
A1: Dashboard Project — Suvidha Finance Ltd. (NBFC Loan Portfolio)
A3: Company
A4: Suvidha Finance Ltd. is a Non-Banking Financial Company (NBFC) that gives out retail loans — Personal Loan, Business Loan, Gold Loan, Vehicle Loan, and Home Improvement Loan — through 8 branches spread across 4 regions (North, South, East, West).
A6: The Business Problem
A7: Every month, each branch manager emails a Word/PDF summary of their loans to the Regional Credit Head and the CFO. Because every branch formats its summary differently and nothing is centralised, leadership currently cannot quickly see:
A8: - whether new loans are being disbursed faster than the company is able to collect on older ones
A9: - which branches, regions, or loan products are quietly building up bad loans (NPAs)
A10: - whether particular customer segments are riskier than others
A11: - which branches/products actually generate the most interest income. i.e. where the real profit is coming from — high disbursement does not automatically mean high profit) | C11: TOTAL LOANS
A12: - how many loans are sitting in the early-warning 'Overdue' zone before they slip into NPA | C12: NPA
C13: OUTSTANDING BALANCE
A14: What is being asked for | C14: TOTAL AMOUNT
A15: A single-page Excel dashboard, built from ONE flat data export (the LoanData sheet in this workbook), that a Regional Credit Head can open at every month-end and get all five answers above at a glance — using PivotTables and PivotCharts/slicers, no manual copy-pasting. | C15: TOTAL OVERDUE
A17: Report date for this dataset
A18: All 'as of' figures (MonthsElapsed, DPD, OutstandingPrincipal, LoanStatus) are calculated as of 31-Jul-2024. Loans in this dataset were disbursed between Jan-2024 and Jun-2024.
A20: Key terms you'll need
A21: NPA (Non-Performing Asset): a loan where the customer has missed payments for more than 90 days (DPD > 90). This is the standard definition used by Indian NBFCs/banks. NPAs are 'bad loans' — money the company may never fully recover.
A22: DPD (Days Past Due): how many days overdue the customer's last missed EMI is. DPD = 0 means fully up to date.
A23: Collection Efficiency: AmountCollectedTillDate as a % of what should have been collected by now — a low number means the branch is struggling to recover money it has already lent out.
A25: The 5 business questions the dashboard must answer
A26: 1. Are we disbursing faster than we're collecting, and is that trend improving or worsening month over month?
A27: 2. Which branches/regions/products have an NPA% that's dangerously high?
A28: 3. Is any customer segment (employment type, age band) disproportionately risky?
A29: 4. Which branches/products generate the most interest income — i.e. where does the profit actually come from?
A30: 5. How many loans are sitting in the 'Overdue' early-warning zone, and where are they concentrated?

Sheet FieldDetails
A1: Field | B1: What it means | C1: Example
A2: LoanID | B2: Unique ID for each loan account. | C2: SFL-10012
A3: BranchName | B3: The branch that originated (sold) the loan. | C3: Chennai-01
A4: Region | B4: The region the branch belongs to. One of North / South / East / West. | C4: South
A5: LoanProduct | B5: The type of loan product. | C5: Personal Loan
A6: CustomerID | B6: Unique ID for the borrowing customer. | C6: CUS-4521
A7: EmploymentType | B7: The customer's employment category, used to study risk by segment. | C7: Self-Employed
A8: CustomerAge | B8: Customer's age in years at disbursement. | C8: 34
A9: DisbursementDate | B9: The date the loan amount was paid out to the customer. | C9: 15-Mar-2024
A10: LoanAmount | B10: The original principal amount disbursed (lent out). | C10: 350000
A11: TenureMonths | B11: Total number of months the customer has to repay the loan. | C11: 36
A12: InterestRate | B12: Annual interest rate charged on the loan, in %. | C12: 14.5
... A20: InterestIncomeEarned | B20: The portion of AmountCollectedTillDate that is interest (i.e. the company's actual profit from this loan so far, not the capital it lent out). | C20: 9850

Sheet pivot tables
A2: total LoanAmount disbursed to total AmountCollectedTillDate for each month.
A3: Row Labels | B3: Sum of AmountCollectedTillDate | C3: Sum of LoanAmount
A4: Jan | B4: 4387565 | C4: 20734000 | J4: =GETPIVOTDATA("Sum of LoanAmount",$A$3) -> 109375000
A5: Feb | B5: 3784489 | C5: 21663000 | F5: =GETPIVOTDATA("Sum of AmountCollectedTillDate",$A$3) -> 13702226
A6: Mar | B6: 2519338 | C6: 21818000
A7: Apr | B7: 1670725 | C7: 20642000
A8: May | B8: 906181 | C8: 13097000
A9: Jun | B9: 433928 | C9: 11421000 | F9: =GETPIVOTDATA("Sum of LoanAmount",$A$3) -> 109375000 | G9: =GETPIVOTDATA("Sum of AmountCollectedTillDate",$A$3) -> 13702226
A10: Grand Total | B10: 13702226 | C10: 109375000
A12: % of total disbursed principal by region
A16: Row Labels | B16: Sum of LoanAmount | C16: Sum of OutstandingPrincipal | D16: Sum of outst%
A17: East | B17: 30653000 | C17: 27528221 | D17: 0.8980596 | F17: =GETPIVOTDATA("Sum of OutstandingPrincipal",$A$16) -> 99301530
A18: North | B18: 27423000 | C18: 25337311 | D18: 0.92394381
A19: South | B19: 24891000 | C19: 22790390 | D19: 0.91560765
A20: West | B20: 26408000 | C20: 23645608 | D20: 0.89539564
A21: Grand Total | B21: 109375000 | C21: 99301530 | D21: 0.9078997
A24: NPA% each branch
A25: Count of LoanID | B25: Column Labels
A26: Row Labels | B26: Active | C26: NPA | D26: Overdue | E26: Grand Total
A27: Bengaluru-01 | B27: 0.66666667 | C27: 0.095238095 | D27: 0.23809524 | E27: 1 | F27: =A27 -> Bengaluru-01 | G27: =GETPIVOTDATA("LoanID",$A$25,"BranchName","Bengaluru-01","LoanStatus","NPA") -> 0.095238095
A28: Bhubaneswar-01 | B28: 0.72 | C28: 0.04 | D28: 0.24 | E28: 1 | F28: =A28 -> Bhubaneswar-01 | G28: =GETPIVOTDATA("LoanID",$A$25,"BranchName","Bhubaneswar-01","LoanStatus","NPA") -> 0.04
A29: Chennai-01 | B29: 0.71428571 | C29: 0.10714286 | D29: 0.17857143 | E29: 1 | F29: =A29 -> Chennai-01 | G29: =GETPIVOTDATA("LoanID",$A$25,"BranchName","Chennai-01","LoanStatus","NPA") -> 0.10714286 | I29: =GETPIVOTDATA("LoanID",$A$25,"LoanStatus","NPA") -> 0.08
A30: Delhi-01 | B30: 0.79166667 | C30: 0.083333333 | D30: 0.125 | E30: 1 | F30: =A30 -> Delhi-01 | G30: =GETPIVOTDATA("LoanID",$A$25,"BranchName","Delhi-01","LoanStatus","NPA") -> 0.083333333
A31: Kolkata-01 | B31: 0.77777778 | C31: 0.074074074 | D31: 0.14814815 | E31: 1 | F31: =A31 -> Kolkata-01 | G31: =GETPIVOTDATA("LoanID",$A$25,"BranchName","Kolkata-01","LoanStatus","NPA") -> 0.074074074
A32: Lucknow-01 | B32: 0.70833333 | C32: 0.083333333 | D32: 0.20833333 | E32: 1 | F32: =A32 -> Lucknow-01 | G32: =GETPIVOTDATA("LoanID",$A$25,"BranchName","Lucknow-01","LoanStatus","NPA") -> 0.083333333 | I32: =GETPIVOTDATA("LoanID",$A$25,"LoanStatus","NPA") -> 0.08
A33: Mumbai-01 | B33: 0.77419355 | C33: 0.064516129 | D33: 0.16129032 | E33: 1 | F33: =A33 -> Mumbai-01 | G33: =GETPIVOTDATA("LoanID",$A$25,"BranchName","Mumbai-01","LoanStatus","NPA") -> 0.064516129
A34: Pune-01 | B34: 0.7 | C34: 0.1 | D34: 0.2 | E34: 1 | F34: =A34 -> Pune-01 | G34: =GETPIVOTDATA("LoanID",$A$25,"BranchName","Pune-01","LoanStatus","NPA") -> 0.1
A35: Grand Total | B35: 0.735 | C35: 0.08 | D35: 0.185 | E35: 1 | F35: =A35 -> Grand Total
A40: NPA% each region
A41: Count of LoanID | B41: Column Labels
A42: Row Labels | B42: Active | C42: NPA | D42: Overdue | E42: Grand Total
A43: East | B43: 0.75 | C43: 0.057692308 | D43: 0.19230769 | E43: 1 | F43: {=A43:A47} -> East | G43: =GETPIVOTDATA("LoanID",$A$41,"Region","East","LoanStatus","NPA") -> 0.057692308 | H43: =GETPIVOTDATA("LoanID",$A$41,"LoanStatus","Overdue") -> 0.185
A44: North | B44: 0.75 | C44: 0.083333333 | D44: 0.16666667 | E44: 1 | F44: North | G44: =GETPIVOTDATA("LoanID",$A$41,"Region","North","LoanStatus","NPA") -> 0.083333333
A45: South | B45: 0.69387755 | C45: 0.10204082 | D45: 0.20408163 | E45: 1 | F45: South | G45: =GETPIVOTDATA("LoanID",$A$41,"Region","South","LoanStatus","NPA") -> 0.10204082
A46: West | B46: 0.74509804 | C46: 0.078431373 | D46: 0.17647059 | E46: 1 | F46: West | G46: =GETPIVOTDATA("LoanID",$A$41,"Region","West","LoanStatus","NPA") -> 0.078431373
A47: Grand Total | B47: 0.735 | C47: 0.08 | D47: 0.185 | E47: 1 | F47: Grand Total
F50: =GETPIVOTDATA("LoanID",$A$41,"LoanStatus","Overdue") -> 0.185
A57: NPA% each product
A58: Count of LoanID | B58: Column Labels
A59: Row Labels | B59: Active | C59: NPA | D59: Overdue | E59: Grand Total
...

Sheet Sheet2

Sheet LoanData
A1: LoanID | B1: BranchName | C1: Region | D1: LoanProduct | E1: CustomerID | F1: EmploymentType | G1: CustomerAge | H1: age catogory | I1: DisbursementDate | J1: LoanAmount | K1: TenureMonths | L1: InterestRate | M1: EMIAmount | N1: MonthsElapsed | O1: InstallmentsPaid | P1: AmountCollectedTillDate | Q1: OutstandingPrincipal | R1: DPD | S1: LoanStatus | T1: InterestIncomeEarned
A2: SFL-10001 | B2: Bengaluru-01 | C2: South | D2: Vehicle Loan | E2: CUS-4001 | F2: Self-Employed | G2: 55 | H2: {=_xlfn.IFS(G2<30,"<30",LoanData!G2<40,"30-40",LoanData!G2<50,"40-50",LoanData!G2>50,"50+")} -> 50+ | I2: 45339 | J2: 989000 | K2: 24 | L2: 11.9 | M2: 46509 | N2: 5 | O2: 5 | P2: 232545 | Q2: 801815 | R2: 0 | S2: Active | T2: 45360
A3: SFL-10002 | B3: Delhi-01 | C3: North | D3: Gold Loan | E3: CUS-4002 | F3: Salaried | G3: 37 | H3: {=_xlfn.IFS(G3<30,"<30",LoanData!G3<40,"30-40",LoanData!G3<50,"40-50",LoanData!G3>50,"50+")} -> 30-40 | I3: 45445 | J3: 281000 | K3: 6 | L3: 10.3 | M3: 48250 | N3: 1 | O3: 1 | P3: 48250 | Q3: 235162 | R3: 0 | S3: Active | T3: 2412
A4: SFL-10003 | B4: Pune-01 | C4: West | D4: Personal Loan | E4: CUS-4003 | F4: Salaried | G4: 46 | H4: {=_xlfn.IFS(G4<30,"<30",LoanData!G4<40,"30-40",LoanData!G4<50,"40-50",LoanData!G4>50,"50+")} -> 40-50 | I4: 45296 | J4: 481000 | K4: 36 | L4: 16.2 | M4: 16958 | N4: 6 | O4: 6 | P4: 101748 | Q4: 416055 | R4: 0 | S4: Active | T4: 36803
A5: SFL-10004 | B5: Delhi-01 | C5: North | D5: Personal Loan | E5: CUS-4004 | F5: Self-Employed | G5: 54 | H5: {=_xlfn.IFS(G5<30,"<30",LoanData!G5<40,"30-40",LoanData!G5<50,"40-50",LoanData!G5>50,"50+")} -> 50+ | I5: 45328 | J5: 254000 | K5: 24 | L5: 16.2 | M5: 12461 | N5: 5 | O5: 5 | P5: 62305 | Q5: 207605 | R5: 0 | S5: Active | T5: 15910
A6: SFL-10005 | B6: Mumbai-01 | C6: West | D6: Personal Loan | E6: CUS-4005 | F6: Business Owner | G6: 27 | H6: {=_xlfn.IFS(G6<30,"<30",LoanData!G6<40,"30-40",LoanData!G6<50,"40-50",LoanData!G6>50,"50+")} -> <30 | I6: 45309 | J6: 401000 | K6: 36 | L6: 14.8 | M6: 13862 | N6: 6 | O6: 6 | P6: 83172 | Q6: 345828 | R6: 0 | S6: Active | T6: 28000
A7: SFL-10006 | B7: Mumbai-01 | C7: West | D7: Gold Loan | E7: CUS-4006 | F7: Self-Employed | G7: 46 | H7: {=_xlfn.IFS(G7<30,"<30",LoanData!G7<40,"30-40",LoanData!G7<50,"40-50",LoanData!G7>50,"50+")} -> 40-50 | I7: 45399 | J7: 278000 | K7: 12 | L7: 11.7 | M7: 24661 | N7: 3 | O7: 3 | P7: 73983 | Q7: 211504 | R7: 0 | S7: Active | T7: 7487
A8: SFL-10007 | B8: Pune-01 | C8: West | D8: Gold Loan | E8: CUS-4007 | F8: Business Owner | G8: 54 | H8: {=_xlfn.IFS(G8<30,"<30",LoanData!G8<40,"30-40",LoanData!G8<50,"40-50",LoanData!G8>50,"50+")} -> 50+ | I8: 45307 | J8: 28000 | K8: 24 | L8: 9.3 | M8: 1283 | N8: 6 | O8: 3 | P8: 3849 | Q8: 24777 | R8: 77 | S8: Overdue | T8: 626
A9: SFL-10008 | B9: Bengaluru-01 | C9: South | D9: Home Improvement Loan | E9: CUS-4008 | F9: Business Owner | G9: 45 | H9: {=_xlfn.IFS(G9<30,"<30",LoanData!G9<40,"30-40",LoanData!G9<50,"40-50",LoanData!G9>50,"50+")} -> 40-50 | I9: 45363 | J9: 785000 | K9: 36 | L9: 11.5 | M9: 25886 | N9: 4 | O9: 4 | P9: 103544 | Q9: 710484 | R9: 0 | S9: Active | T9: 29028
A10: SFL-10009 | B10: Kolkata-01 | C10: East | D10: Personal Loan | E10: CUS-4009 | F10: Self-Employed | G10: 46 | H10: {=_xlfn.IFS(G10<30,"<30",LoanData!G10<40,"30-40",LoanData!G10<50,"40-50",LoanData!G10>50,"50+")} -> 40-50 | I10: 45344 | J10: 126000 | K10: 12 | L10: 17.7 | M10: 11534 | N10: 5 | O10: 0 | P10: 0 | Q10: 126000 | R10: 224 | S10: NPA | T10: 0
A11: SFL-10010 | B11: Bengaluru-01 | C11: South | D11: Business Loan | E11: CUS-4010 | F11: Self-Employed | G11: 55 | H11: {=_xlfn.IFS(G11<30,"<30",LoanData!G11<40,"30-40",LoanData!G11<50,"40-50",LoanData!G11>50,"50+")} -> 50+ | I11: 45404 | J11: 1931000 | K11: 48 | L11: 14.4 | M11: 53156 | N11: 3 | O11: 2 | P11: 106312 | Q11: 1870673 | R11: 32 | S11: Overdue | T11: 45985
A12: SFL-10011 | B12: Chennai-01 | C12: South | D12: Vehicle Loan | E12: CUS-4011 | F12: Salaried | G12: 41 | H12: {=_xlfn.IFS(G12<30,"<30",LoanData!G12<40,"30-40",LoanData!G12<50,"40-50",LoanData!G12>50,"50+")} -> 40-50 | I12: 45319 | J12: 1227000 | K12: 36 | L12: 13.1 | M12: 41402 | N12: 6 | O12: 6 | P12: 248412 | Q12: 1054305 | R12: 0 | S12: Active | T12: 75717
A13: SFL-10012 | B13: Kolkata-01 | C13: East | D13: Vehicle Loan | E13: CUS-4012 | F13: Business Owner | G13: 32 | H13: {=_xlfn.IFS(G13<30,"<30",LoanData!G13<40,"30-40",LoanData!G13<50,"40-50",LoanData!G13>50,"50+")} -> 30-40 | I13: 45346 | J13: 448000 | K13: 36 | L13: 11.6 | M13: 14795 | N13: 5 | O13: 5 | P13: 73975 | Q13: 394659 | R13: 0 | S13: Active | T13: 20634
... A27: SFL-10026 | B27: Mumbai-01 | C27: West | D27: Business Loan | E27: CUS-4026 | F27: Business Owner | G27: 32 | H27: {=_xlfn.IFS(G27<30,"<30",LoanData!G27<40,"30-40",LoanData!G27<50,"40-50",LoanData!G27>50,"50+")} -> 30-40 | I27: 45309 | J27: 763000 | K27: 60 | L27: 13.2 | M27: 17439 | N27: 6 | O27: 0 | P27: 0 | Q27: 763000 | R27: 224 | S27: NPA | T27: 0
A28: SFL-10027 | B28: Bhubaneswar-01 | C28: East | D28: Vehicle Loan | E28: CUS-4027 | F28: Business Owner | G28: 50 | H28: {=_xlfn.IFS(G28<30,"<30",LoanData!G28<40,"30-40",LoanData!G28<50,"40-50",LoanData!G28>=50,"50+")} -> 50+ | I28: 45344 | J28: 1476000 | K28: 24 | L28: 14 | M28: 70867 | N28: 5 | O28: 5 | P28: 354335 | Q28: 1201433 | R28: 0 | S28: Active | T28: 79768
A29: SFL-10028 | B29: Bengaluru-01 | C29: South | D29: Personal Loan | E29: CUS-4028 | F29: Salaried | G29: 55 | H29: {=_xlfn.IFS(G29<30,"<30",LoanData!G29<40,"30-40",LoanData!G29<50,"40-50",LoanData!G29>=50,"50+")} -> 50+ | I29: 45330 | J29: 478000 | K29: 24 | L29: 15.3 | M29: 23245 | N29: 5 | O29: 5 | P29: 116225 | Q29: 390034 | R29: 0 | S29: Active | T29: 28259
A30: SFL-10029 | B30: Bhubaneswar-01 | C30: East | D30: Business Loan | E30: CUS-4029 | F30: Self-Employed | G30: 40 | H30: {=_xlfn.IFS(G30<30,"<30",LoanData!G30<40,"30-40",LoanData!G30<50,"40-50",LoanData!G30>=50,"50+")} -> 40-50 | I30: 45449 | J30: 1893000 | K30: 60 | L30: 13.9 | M30: 43949 | N30: 1 | O30: 1 | P30: 43949 | Q30: 1870979 | R30: 0 | S30: Active | T30: 21928
A31: SFL-10030 | B31: Kolkata-01 | C31: East | D31: Business Loan | E31: CUS-4030 | F31: Business Owner | G31: 46 | H31: {=_xlfn.IFS(G31<30,"<30",LoanData!G31<40,"30-40",LoanData!G31<50,"40-50",LoanData!G31>=50,"50+")} -> 40-50 | I31: 45294 | J31: 1955000 | K31: 48 | L31: 12.9 | M31: 52351 | N31: 6 | O31: 6 | P31: 314106 | Q31: 1761867 | R31: 0 | S31: Active | T31: 120973
A32: SFL-10031 | B32: Lucknow-01 | C32: North | D32: Home Improvement Loan | E32: CUS-4031 | F32: Business Owner | G32: 32 | H32: {=_xlfn.IFS(G32<30,"<30",LoanData!G32<40,"30-40",LoanData!G32<50,"40-50",LoanData!G32>=50,"50+")} -> 30-40 | I32: 45301 | J32: 381000 | K32: 24 | L32: 12.8 | M32: 18078 | N32: 6 | O32: 4 | P32: 72312 | Q32: 324042 | R32: 48 | S32: Overdue | T32: 15354
A33: SFL-10032 | B33: Lucknow-01 | C33: North | D33: Business Loan | E33: CUS-4032 | F33: Business Owner | G33: 26 | H33: {=_xlfn.IFS(G33<30,"<30",LoanData!G33<40,"30-40",LoanData!G33<50,"40-50",LoanData!G33>=50,"50+")} -> <30 | I33: 45358 | J33: 443000 | K33: 60 | L33: 15.2 | M33: 10586 | N33: 4 | O33: 2 | P33: 21172 | Q33: 432989 | R33: 71 | S33: Overdue | T33: 11161
A34: SFL-10033 | B34: Chennai-01 | C34: South | D34: Home Improvement Loan | E34: CUS-4033 | F34: Salaried | G34: 27 | H34: {=_xlfn.IFS(G34<30,"<30",LoanData!G34<40,"30-40",LoanData!G34<50,"40-50",LoanData!G34>=50,"50+")} -> <30 | I34: 45305 | J34: 652000 | K34: 60 | L34: 14.4 | M34: 15306 | N34: 6 | O34: 6 | P34: 91836 | Q34: 605737 | R34: 0 | S34: Active | T34: 45573
A35: SFL-10034 | B35: Chennai-01 | C35: South | D35: Personal Loan | E35: CUS-4034 | F35: Business Owner | G35: 54 | H35: {=_xlfn.IFS(G35<30,"<30",LoanData!G35<40,"30-40",LoanData!G35<50,"40-50",LoanData!G35>=50,"50+")} -> 50+ | I35: 45404 | J35: 274000 | K35: 36 | L35: 16.1 | M35: 9647 | N35: 3 | O35: 3 | P35: 28941 | Q35: 255847 | R35: 0 | S35: Active | T35: 10788
A36: SFL-10035 | B36: Kolkata-01 | C36: East | D36: Gold Loan | E36: CUS-4035 | F36: Business Owner | G36: 23 | H36: {=_xlfn.IFS(G36<30,"<30",LoanData!G36<40,"30-40",LoanData!G36<50,"40-50",LoanData!G36>=50,"50+")} -> <30 | I36: 45313 | J36: 63000 | K36: 24 | L36: 9.9 | M36: 2904 | N36: 6 | O36: 4 | P36: 11616 | Q36: 53343 | R36: 66 | S36: Overdue | T36: 1959
A37: SFL-10036 | B37: Delhi-01 | C37: North | D37: Gold Loan | E37: CUS-4036 | F37: Business Owner | G37: 54 | H37: {=_xlfn.IFS(G37<30,"<30",LoanData!G37<40,"30-40",LoanData!G37<50,"40-50",LoanData!G37>=50,"50+")} -> 50+ | I37: 45373 | J37: 96000 | K37: 6 | L37: 9.2 | M37: 16432 | N37: 4 | O37: 4 | P37: 65728 | Q37: 32490 | R37: 0 | S37: Active | T37: 2218
A38: SFL-10037 | B38: Mumbai-01 | C38: West | D38: Personal Loan | E38: CUS-4037 | F38: Self-Employed | G38: 49 | H38: {=_xlfn.IFS(G38<30,"<30",LoanData!G38<40,"30-40",LoanData!G38<50,"40-50",LoanData!G38>=50,"50+")} -> 40-50 | I38: 45345 | J38: 97000 | K38: 36 | L38: 17.7 | M38: 3492 | N38: 5 | O38: 3 | P38: 10476 | Q38: 90724 | R38: 68 | S38: Overdue | T38: 4200
A39: SFL-10038 | B39: Mumbai-01 | C39: West | D39: Gold Loan | E39: CUS-4038 | F39: Business Owner | G39: 45 | H39: {=_xlfn.IFS(G39<30,"<30",LoanData!G39<40,"30-40",LoanData!G39<50,"40-50",LoanData!G39>=50,"50+")} -> 40-50 | I39: 45430 | J39: 252000 | K39: 6 | L39: 9.6 | M39: 43184 | N39: 2 | O39: 2 | P39: 86368 | Q39: 169335 | R39: 0 | S39: Active | T39: 3703
... A201: SFL-10200 | B201: Pune-01 | C201: West | D201: Vehicle Loan | E201: CUS-4200 | F201: Business Owner | G201: 58 | H201: {=_xlfn.IFS(G201<30,"<30",LoanData!G201<40,"30-40",LoanData!G201<50,"40-50",LoanData!G201>=50,"50+")} -> 50+ | I201: 45326 | J201: 1158000 | K201: 48 | L201: 10 | M201: 29370 | N201: 5 | O201: 4 | P201: 117480 | Q201: 1078129 | R201: 35 | S201: Overdue | T201: 37609

Sheet PivotProblems
A1: Dashboard Build Questions
A3: A. Disbursement vs. Collection Health
A4: # | B4: Question (answers a business question) | C4: Build this as... | D4: Your Answer / Notes
A5: 1 | B5: Compare total LoanAmount disbursed to total AmountCollectedTillDate for each month.
A6: 2 | B6: Is the gap between disbursement and collection widening or narrowing month over month?
A7: 3 | B7: What % of total disbursed principal remains outstanding right now, overall and by region? | C7: usin inser field n calculate field
A9: B. Branch / Region / Product Risk (NPA%)
A10: # | B10: Question (answers a business question) | C10: Build this as... | D10: Your Answer / Notes
A11: 1 | B11: What is the NPA% (NPA loans as a % of total loans) for each branch?
A12: 2 | B12: Which region has the highest NPA% by outstanding value, not just by loan count?
A13: 3 | B13: Which loan product carries the most NPA risk?
A14: 4 | B14: Rank all 8 branches from healthiest to riskiest, using NPA% as the ranking measure.
A16: C. Customer Segment Risk
A17: # | B17: Question (answers a business question) | C17: Build this as... | D17: Your Answer / Notes
A18: 1 | B18: Does EmploymentType affect default risk? Compare NPA% across Salaried, Self-Employed, and Business Owner.
A19: 2 | B19: Group customers into age bands (e.g. <30, 30-40, 40-50, 50+) and compare NPA% across bands.
A20: 3 | B20: Within the riskiest EmploymentType found above, which LoanProduct is most commonly involved in NPAs?
A22: D. Profitability (Interest Income)
A23: # | B23: Question (answers a business question) | C23: Build this as... | D23: Your Answer / Notes
A24: 1 | B24: Which branch has earned the most InterestIncomeEarned so far?
A25: 2 | B25: Which LoanProduct is the most profitable per rupee lent (InterestIncomeEarned as a % of LoanAmount)? | C25: usin inser field n calculate field.(interestIncomeEarned / LoanAmount)
A26: 3 | B26: Is the branch with the HIGHEST disbursement also the branch with the highest interest income? What does a mismatch tell you?
A28: E. Early-Warning (DPD / Overdue Monitoring)
A29: # | B29: Question (answers a business question) | C29: Build this as... | D29: Your Answer / Notes
A30: 1 | B30: How many loans are currently in the 'Overdue' zone (1-90 DPD) and what total OutstandingPrincipal do they represent?
A31: 2 | B31: Which branch has the most loans sitting in the Overdue zone (i.e. at risk of becoming NPA next)?
A32: 3 | B32: Build a single dashboard view combining Region, LoanProduct, and LoanStatus with a slicer, so a manager can filter to any one region/product and instantly see the loan-status split.

Sheet RISK ANALYSIS DASHBORD

Sheet MAIN DASHBORD
